Workbook

Sheet Europcar rates
A1: Europcar Rates (As on 29/04/2026)
A3: Location | B3: Vehicle Class | C3: Low Season Manual | D3: Low Season Auto | E3: High Season Manual | F3: High Season Auto | G3: Lookup Key
A4: Dublin Airport | B4: Economy (Small Car) | C4: =148/7 -> 21.142857 | D4: =248/7 -> 35.428571 | E4: =176/7 -> 25.142857 | F4: =303/7 -> 43.285714 | G4: =A4& " | "&B4 -> Dublin Airport | Economy (Small Car)
A5: Dublin Airport | B5: Compact (Medium Car) | C5: =167/7 -> 23.857143 | D5: =266/7 -> 38 | E5: =190/7 -> 27.142857 | F5: =329/7 -> 47 | G5: =A5& " | "&B5 -> Dublin Airport | Compact (Medium Car)
A6: Dublin Airport | B6: SUV | C6: =207/7 -> 29.571429 | D6: =280/7 -> 40 | E6: =227/7 -> 32.428571 | F6: =385/7 -> 55 | G6: =A6& " | "&B6 -> Dublin Airport | SUV
A7: Dublin Airport | B7: People carrier | C7: - | D7: =596/7 -> 85.142857 | E7: - | F7: =664/7 -> 94.857143 | G7: =A7& " | "&B7 -> Dublin Airport | People carrier
A9: Cork Airport | B9: Economy (Small Car) | C9: =148/7 -> 21.142857 | D9: =248/7 -> 35.428571 | E9: =176/7 -> 25.142857 | F9: =303/7 -> 43.285714 | G9: =A9&" | "&B9 -> Cork Airport | Economy (Small Car)
A10: Cork Airport | B10: Compact (Medium Car) | C10: =167/7 -> 23.857143 | D10: =266/7 -> 38 | E10: =190/7 -> 27.142857 | F10: =329/7 -> 47 | G10: =A10&" | "&B10 -> Cork Airport | Compact (Medium Car)
A11: Cork Airport | B11: SUV | C11: =207/7 -> 29.571429 | D11: =316/7 -> 45.142857 | E11: =227/7 -> 32.428571 | F11: =385/7 -> 55 | G11: =A11&" | "&B11 -> Cork Airport | SUV
A12: Cork Airport | B12: People carrier | C12: - | D12: - | E12: - | F12: - | G12: =A12&" | "&B12 -> Cork Airport | People carrier
A14: Shannon Airport | B14: Economy (Small Car) | C14: =148/7 -> 21.142857 | D14: =248/7 -> 35.428571 | E14: =176/7 -> 25.142857 | F14: =303/7 -> 43.285714 | G14: =A14&" | "&B14 -> Shannon Airport | Economy (Small Car)
A15: Shannon Airport | B15: Compact (Medium Car) | C15: =167/7 -> 23.857143 | D15: =266/7 -> 38 | E15: =190/7 -> 27.142857 | F15: =329/7 -> 47 | G15: =A15&" | "&B15 -> Shannon Airport | Compact (Medium Car)
A16: Shannon Airport | B16: SUV | C16: =207/7 -> 29.571429 | D16: =316/7 -> 45.142857 | E16: =227/7 -> 32.428571 | F16: =385/7 -> 55 | G16: =A16&" | "&B16 -> Shannon Airport | SUV
A17: Shannon Airport | B17: People carrier | C17: - | D17: - | E17: - | F17: - | G17: =A17&" | "&B17 -> Shannon Airport | People carrier
A19: Galway | B19: Economy (Small Car) | C19: =161/7 -> 23 | D19: =261/7 -> 37.285714 | E19: =193/7 -> 27.571429 | F19: =318/7 -> 45.428571 | G19: =A19&" | "&B19 -> Galway | Economy (Small Car)
A20: Galway | B20: Compact (Medium Car) | C20: =176/7 -> 25.142857 | D20: =281/7 -> 40.142857 | E20: =200/7 -> 28.571429 | F20: =346/7 -> 49.428571 | G20: =A20&" | "&B20 -> Galway | Compact (Medium Car)
A21: Galway | B21: SUV | C21: =221/7 -> 31.571429 | D21: =335/7 -> 47.857143 | E21: =241/7 -> 34.428571 | F21: =406/7 -> 58 | G21: =A21&" | "&B21 -> Galway | SUV
A22: Galway | B22: People carrier | C22: - | D22: - | E22: - | F22: - | G22: =A22&" | "&B22 -> Galway | People carrier
A24: Source site | B24: rentalcars.com
A26: Dates consider for above data
A27: Dates consider for Low Season | B27: 9-June-2026 to 16-June-2026
A28: Dates consider for High Season | B28: 14-July- 2026 to 21-July- 2026
A31: Cars in each class
A32: Economy | B32: Ford Ka, Toyota Aygo X, Volkswagen Polo, Ford Fiesta
A33: Compact | B33: Opel Astra, Ford Focus, Toyota Auris, Seat Leon
A34: SUV | B34: Renault Captur, Nissan Juke, Nissan Qashqai, Ford Puma, Volkswagen T-cross
A35: People carrier | B35: Renault Trafic, Ford Transit, Nissan Qashqai,Skoda Kodiaq, Dacia Jogger, Volkswagen Caddy
A38: Notes
A39: 1 | B39: Rates collected 29 Apr 2026 via rentalcars.com — lowest available rate per class recorded
A40: 2 | B40: Low season represented by June 2026 — January 2027 rates excluded due to incomplete inventory loading and advance booking distortion. Initially consider as 11-January-2027 to 18- January- 2027
A43: 3 | B43: No People Carrier available in Cork,Shannon
A44: 4 | B44: SUV Automatic cheaper in Dublin as we have another car available under SUV at cheaper rate
A45: 5 | B45: No as such big seven seater car with Europcar, as seen sister concern Go Car provides seven seater at hourly and cheaper rate

Sheet Competitor's Rate
A1: Competitor's Rate (County-wise) -As on 29/04/2026
A4: Dublin Airport | G4: Cork Airport | M4: Shannon Airport | S4: Galway
B5: Hertz | C5: Avis | D5: Enterprise | E5: Budget | F5: Sixt | H5: =B5 -> Hertz | I5: =C5 -> Avis | J5: =D5 -> Enterprise | K5: =E5 -> Budget | L5: =F5 -> Sixt | N5: =H5 -> Hertz | O5: =I5 -> Avis | P5: =J5 -> Enterprise | Q5: =K5 -> Budget | R5: =L5 -> Sixt | T5: =N5 -> Hertz | U5: =O5 -> Avis | V5: =P5 -> Enterprise | W5: =Q5 -> Budget | X5: =R5 -> Sixt
A6: Class | B6: Economy (Small Car) | G6: =A6 -> Class | H6: Economy (Small Car) | M6: =G6 -> Class | N6: =H6 -> Economy (Small Car) | S6: =M6 -> Class | T6: =N6 -> Economy (Small Car)
A7: {=TRANSPOSE('Europcar rates'!C3:F3)} -> Low Season Manual | B7: =155/7 -> 22.142857 | C7: =160/7 -> 22.857143 | D7: =270/7 -> 38.571429 | E7: =116/7 -> 16.571429 | F7: =140/7 -> 20 | G7: =A7 -> Low Season Manual | H7: =160/7 -> 22.857143 | I7: =165/7 -> 23.571429 | J7: =370/7 -> 52.857143 | K7: =116/7 -> 16.571429 | L7: =140/7 -> 20 | M7: =G7 -> Low Season Manual | N7: =155/7 -> 22.142857 | O7: =165/7 -> 23.571429 | P7: =370/7 -> 52.857143 | Q7: =113/7 -> 16.142857 | R7: =228/7 -> 32.571429 | S7: =M7 -> Low Season Manual | T7: - | U7: - | V7: =281/7 -> 40.142857 | W7: =233/7 -> 33.285714 | X7: -
A8: Low Season Auto | B8: =260/7 -> 37.142857 | C8: =260/7 -> 37.142857 | D8: =887/7 -> 126.71429 | E8: =210/7 -> 30 | F8: =217/7 -> 31 | G8: =A8 -> Low Season Auto | H8: =260/7 -> 37.142857 | I8: =274/7 -> 39.142857 | J8: =510/7 -> 72.857143 | K8: =210/7 -> 30 | L8: =217/7 -> 31 | M8: =G8 -> Low Season Auto | N8: =260/7 -> 37.142857 | O8: =274/7 -> 39.142857 | P8: =481/7 -> 68.714286 | Q8: =210/7 -> 30 | R8: =277/7 -> 39.571429 | S8: =M8 -> Low Season Auto | T8: - | U8: - | V8: =308/7 -> 44 | W8: =377/7 -> 53.857143 | X8: -
A9: High Season Manual | B9: =184/7 -> 26.285714 | C9: =192/7 -> 27.428571 | D9: =350/7 -> 50 | E9: =150/7 -> 21.428571 | F9: =228/7 -> 32.571429 | G9: =A9 -> High Season Manual | H9: =184/7 -> 26.285714 | I9: =192/7 -> 27.428571 | J9: =500/7 -> 71.428571 | K9: =150/7 -> 21.428571 | L9: =162/7 -> 23.142857 | M9: =G9 -> High Season Manual | N9: =184/7 -> 26.285714 | O9: =192/7 -> 27.428571 | P9: =370/7 -> 52.857143 | Q9: =150/7 -> 21.428571 | R9: =162/7 -> 23.142857 | S9: =M9 -> High Season Manual | T9: - | U9: - | V9: =281/7 -> 40.142857 | W9: =453/7 -> 64.714286 | X9: -
A10: High Season Auto | B10: =318/7 -> 45.428571 | C10: =317/7 -> 45.285714 | D10: =787/7 -> 112.42857 | E10: =263/7 -> 37.571429 | F10: =277/7 -> 39.571429 | G10: =A10 -> High Season Auto | H10: =318/7 -> 45.428571 | I10: =317/7 -> 45.285714 | J10: =776/7 -> 110.85714 | K10: =263/7 -> 37.571429 | L10: =264/7 -> 37.714286 | M10: =G10 -> High Season Auto | N10: =318/7 -> 45.428571 | O10: =317/7 -> 45.285714 | P10: =776/7 -> 110.85714 | Q10: =263/7 -> 37.571429 | R10: =264/7 -> 37.714286 | S10: =M10 -> High Season Auto | T10: - | U10: - | V10: =308/7 -> 44 | W10: =822/7 -> 117.42857 | X10: -
A12: Class | B12: Compact (Medium Car) | G12: =A12 -> Class | H12: =B12 -> Compact (Medium Car) | M12: =G12 -> Class | N12: =H12 -> Compact (Medium Car) | S12: =M12 -> Class | T12: =N12 -> Compact (Medium Car)
A13: =A7 -> Low Season Manual | B13: =175/7 -> 25 | C13: =175/7 -> 25 | D13: =356/7 -> 50.857143 | E13: =133/7 -> 19 | F13: =153/7 -> 21.857143 | G13: =A13 -> Low Season Manual | H13: =175/7 -> 25 | I13: =180/7 -> 25.714286 | J13: =409/7 -> 58.428571 | K13: =133/7 -> 19 | L13: =153/7 -> 21.857143 | M13: =G13 -> Low Season Manual | N13: =175/7 -> 25 | O13: =180/7 -> 25.714286 | P13: =409/7 -> 58.428571 | Q13: =133/7 -> 19 | R13: =249/7 -> 35.571429 | S13: =M13 -> Low Season Manual | T13: - | U13: - | V13: =309/7 -> 44.142857 | W13: =279/7 -> 39.857143 | X13: -
A14: =A8 -> Low Season Auto | B14: =280/7 -> 40 | C14: =280/7 -> 40 | D14: =448/7 -> 64 | E14: =230/7 -> 32.857143 | F14: =238/7 -> 34 | G14: =A14 -> Low Season Auto | H14: =280/7 -> 40 | I14: =294/7 -> 42 | J14: =580/7 -> 82.857143 | K14: =230/7 -> 32.857143 | L14: =238/7 -> 34 | M14: =G14 -> Low Season Auto | N14: =280/7 -> 40 | O14: =294/7 -> 42 | P14: =580/7 -> 82.857143 | Q14: =230/7 -> 32.857143 | R14: =304/7 -> 43.428571 | S14: =M14 -> Low Season Auto | T14: - | U14: - | V14: =321/7 -> 45.857143 | W14: =474/7 -> 67.714286 | X14: -
A15: =A9 -> High Season Manual | B15: =200/7 -> 28.571429 | C15: =199/7 -> 28.428571 | D15: =473/7 -> 67.571429 | E15: =168/7 -> 24 | F15: =249/7 -> 35.571429 | G15: =A15 -> High Season Manual | H15: =200/7 -> 28.571429 | I15: =199/7 -> 28.428571 | J15: =550/7 -> 78.571429 | K15: =168/7 -> 24 | L15: =177/7 -> 25.285714 | M15: =G15 -> High Season Manual | N15: =200/7 -> 28.571429 | O15: =199/7 -> 28.428571 | P15: =409/7 -> 58.428571 | Q15: =168/7 -> 24 | R15: =177/7 -> 25.285714 | S15: =M15 -> High Season Manual | T15: - | U15: - | V15: =309/7 -> 44.142857 | W15: =538/7 -> 76.857143 | X15: -
A16: =A10 -> High Season Auto | B16: =345/7 -> 49.285714 | C16: =345/7 -> 49.285714 | D16: =579/7 -> 82.714286 | E16: =350/7 -> 50 | F16: =304/7 -> 43.428571 | G16: =A16 -> High Season Auto | H16: =345/7 -> 49.285714 | I16: =345/7 -> 49.285714 | J16: =821/7 -> 117.28571 | K16: =350/7 -> 50 | L16: =290/7 -> 41.428571 | M16: =G16 -> High Season Auto | N16: =345/7 -> 49.285714 | O16: =345/7 -> 49.285714 | P16: =813/7 -> 116.14286 | Q16: =350/7 -> 50 | R16: =290/7 -> 41.428571 | S16: =M16 -> High Season Auto | T16: - | U16: - | V16: =321/7 -> 45.857143 | W16: =848/7 -> 121.14286 | X16: -
A18: Class | B18: SUV | G18: =A18 -> Class | H18: =B18 -> SUV | M18: =G18 -> Class | N18: =H18 -> SUV | S18: =M18 -> Class | T18: =N18 -> SUV
A19: =A13 -> Low Season Manual | B19: =185/7 -> 26.428571 | C19: =185/7 -> 26.428571 | D19: =376/7 -> 53.714286 | E19: =169/7 -> 24.142857 | F19: =155/7 -> 22.142857 | G19: =A19 -> Low Season Manual | H19: =185/7 -> 26.428571 | I19: =190/7 -> 27.142857 | J19: =429/7 -> 61.285714 | K19: =169/7 -> 24.142857 | L19: =155/7 -> 22.142857 | M19: =G19 -> Low Season Manual | N19: =185/7 -> 26.428571 | O19: =190/7 -> 27.142857 | P19: =429/7 -> 61.285714 | Q19: =169/7 -> 24.142857 | R19: =253/7 -> 36.142857 | S19: =M19 -> Low Season Manual | T19: - | U19: - | V19: =324/7 -> 46.285714 | W19: =315/7 -> 45 | X19: -
A20: =A14 -> Low Season Auto | B20: =335/7 -> 47.857143 | C20: =334/7 -> 47.714286 | D20: =446/7 -> 63.714286 | E20: =407/7 -> 58.142857 | F20: =239/7 -> 34.142857 | G20: =A20 -> Low Season Auto | H20: =335/7 -> 47.857143 | I20: =359/7 -> 51.285714 | J20: =612/7 -> 87.428571 | K20: =407/7 -> 58.142857 | L20: =239/7 -> 34.142857 | M20: =G20 -> Low Season Auto | N20: =335/7 -> 47.857143 | O20: =359/7 -> 51.285714 | P20: =644/7 -> 92 | Q20: =407/7 -> 58.142857 | R20: =305/7 -> 43.571429 | S20: =M20 -> Low Season Auto | T20: - | U20: - | V20: =331/7 -> 47.285714 | W20: =596/7 -> 85.142857 | X20: -
A21: =A15 -> High Season Manual | B21: =210/7 -> 30 | C21: =209/7 -> 29.857143 | D21: =487/7 -> 69.571429 | E21: =216/7 -> 30.857143 | F21: =253/7 -> 36.142857 | G21: =A21 -> High Season Manual | H21: =210/7 -> 30 | I21: =209/7 -> 29.857143 | J21: =577/7 -> 82.428571 | K21: =216/7 -> 30.857143 | L21: =189/7 -> 27 | M21: =G21 -> High Season Manual | N21: =210/7 -> 30 | O21: =209/7 -> 29.857143 | P21: =429/7 -> 61.285714 | Q21: =216/7 -> 30.857143 | R21: =189/7 -> 27 | S21: =M21 -> High Season Manual | T21: - | U21: - | V21: =324/7 -> 46.285714 | W21: =664/7 -> 94.857143 | X21: -
A22: =A16 -> High Season Auto | B22: =405/7 -> 57.857143 | C22: =405/7 -> 57.857143 | D22: =579/7 -> 82.714286 | E22: =456/7 -> 65.142857 | F22: =305/7 -> 43.571429 | G22: =A22 -> High Season Auto | H22: =405/7 -> 57.857143 | I22: =405/7 -> 57.857143 | J22: =855/7 -> 122.14286 | K22: =456/7 -> 65.142857 | L22: =305/7 -> 43.571429 | M22: =G22 -> High Season Auto | N22: =405/7 -> 57.857143 | O22: =405/7 -> 57.857143 | P22: =896/7 -> 128 | Q22: =456/7 -> 65.142857 | R22: =305/7 -> 43.571429 | S22: =M22 -> High Season Auto | T22: - | U22: - | V22: =331/7 -> 47.285714 | W22: =1077/7 -> 153.85714 | X22: -
A24: Class | B24: People carrier | G24: =A24 -> Class | H24: =B24 -> People carrier | M24: =G24 -> Class | N24: =H24 -> People carrier | S24: =M24 -> Class | T24: =N24 -> People carrier
A25: =A19 -> Low Season Manual | B25: - | C25: =1350/7 -> 192.85714 | D25: - | E25: =730/7 -> 104.28571 | F25: - | G25: =A25 -> Low Season Manual | H25: - | I25: =1350/7 -> 192.85714 | J25: - | K25: =730/7 -> 104.28571 | L25: - | M25: =G25 -> Low Season Manual | N25: - | O25: =1350/7 -> 192.85714 | P25: - | Q25: =730/7 -> 104.28571 | R25: - | S25: =M25 -> Low Season Manual | T25: - | U25: - | V25: - | W25: =852/7 -> 121.71429 | X25: -
A26: =A20 -> Low Season Auto | B26: =3885/7 -> 555 | C26: =1550/7 -> 221.42857 | D26: =1034/7 -> 147.71429 | E26: =3013/7 -> 430.42857 | F26: =1807/7 -> 258.14286 | G26: =A26 -> Low Season Auto | H26: =3885/7 -> 555 | I26: =1550/7 -> 221.42857 | J26: =1256/7 -> 179.42857 | K26: =3013/7 -> 430.42857 | L26: - | M26: =G26 -> Low Season Auto | N26: =3885/7 -> 555 | O26: =1550/7 -> 221.42857 | P26: =1256/7 -> 179.42857 | Q26: =3013/7 -> 430.42857 | R26: - | S26: =M26 -> Low Season Auto | T26: - | U26: - | V26: =592/7 -> 84.571429 | W26: =1737/7 -> 248.14286 | X26: -
A27: =A21 -> High Season Manual | B27: - | C27: =1703/7 -> 243.28571 | D27: - | E27: =644/7 -> 92 | F27: =2374/7 -> 339.14286 | G27: =A27 -> High Season Manual | H27: - | I27: =1703/7 -> 243.28571 | J27: - | K27: =644/7 -> 92 | L27: - | M27: =G27 -> High Season Manual | N27: - | O27: =1703/7 -> 243.28571 | P27: - | Q27: =644/7 -> 92 | R27: - | S27: =M27 -> High Season Manual | T27: - | U27: - | V27: - | W27: =1218/7 -> 174 | X27: -
A28: =A22 -> High Season Auto | B28: =2100/7 -> 300 | C28: =2032/7 -> 290.28571 | D28: =1340/7 -> 191.42857 | E28: =1461/7 -> 208.71429 | F28: - | G28: =A28 -> High Season Auto | H28: =2100/7 -> 300 | I28: =2032/7 -> 290.28571 | J28: =1350/7 -> 192.85714 | K28: =1461/7 -> 208.71429 | L28: - | M28: =G28 -> High Season Auto | N28: =2100/7 -> 300 | O28: =2032/7 -> 290.28571 | P28: =1758/7 -> 251.14286 | Q28: =1461/7 -> 208.71429 | R28: - | S28: =M28 -> High Season Auto | T28: - | U28: - | V28: =529/7 -> 75.571429 | W28: =2009/7 -> 287 | X28: -
A31: Source site | B31: rentalcars.com
A33: Dates consider for above data
A34: Dates consider for Low Season | B34: 9-June-2026 to 16-June-2026
A35: Dates consider for High Season | B35: 14-July- 2026 to 21-July- 2026
A37: Notes
A38: 1 | B38: Budget (Cork): People carrier only VW Caddy available price is that high compare to manual as there is an cheaper option of Dacia Jogger
A40: 2 | B40: People Carrier segment shows inverted seasonality — low season rates exceed high season due to corporate travel demand, limited fleet availability and reduced competition outside peak tourist season.
A43: 3 | B43: I noticed the People Carrier segment showed an unusual pricing pattern — low season rates were actually higher than high season. This told me that seasonality affects different vehicle classes differently, and that a one-size-fits-all pricing approach wouldn't work across all segments.
A46: 4 | B46: Hertz, Avis and Sixt do not operate at Galway. Only Enterprise and Budget provide car rental services at this location. Competitor analysis for Galway is therefore based on two suppliers only. This limited competition may contribute to higher pricing observed in this market.
A48: 5 | B48: High difference between Automatic vehicle in high and low season seen significantly in Enterprises

Sheet Variance Analysis
A1: VARIANCE ANALYSIS — EUROPCAR vs COMPETITORS (with XLOOKUP)
A2: Green text = cross-sheet XLOOKUP | Blue text = hardcoded inputs | Black = formulas | ✅ Below Market = Europcar cheaper | 🟡 At Market = within ±10% | 🔴 Above Market = >10% above avg
A3: XLOOKUP formula used: =XLOOKUP(A_row&" | "&B_row, 'Europcar rates'!G:G, 'Europcar rates'!C:F) — looks up "Location | Class" key in helper column G and returns the matching rate
A4: Location | B4: Vehicle Class | C4: Season Type | D4: Hertz (€/day) | E4: Avis (€/day) | F4: Enterprise (€/day) | G4: Budget (€/day) | H4: Sixt (€/day) | I4: Comp Avg (€/day) | J4: Comp Min (€/day) | K4: Comp Max (€/day) | L4: Europcar (XLOOKUP €/day) | M4: vs Avg (%) | N4: Position | O4: Recommendation | P4: Lookup Key
A5: Dublin Airport | B5: Economy (Small Car) | C5: Low Season Manual | D5: ='Competitor''s Rate'!B7 -> 22.142857 | E5: ='Competitor''s Rate'!C7 -> 22.857143 | F5: ='Competitor''s Rate'!D7 -> 38.571429 | G5: ='Competitor''s Rate'!E7 -> 16.571429 | H5: ='Competitor''s Rate'!F7 -> 20 | I5: =IFERROR(AVERAGEIF(D5:H5,">"&0),"-") -> 24.028571 | J5: =IFERROR(_xlfn.MINIFS(D5:H5,D5:H5,">"&0),"-") -> 16.571429 | K5: =IFERROR(MAX(D5:H5),"-") -> 38.571429 | L5: =IFERROR(_xlfn.XLOOKUP(P5,'Europcar rates'!G:G,'Europcar rates'!C:C),"-") -> 21.142857 | M5: =IFERROR((L5-I5)/I5,"-") -> -0.12009512 | N5: =IFERROR(IF(L5<=I5*0.9,"✅ Below Market",IF(L5<=I5*1.1,"🟡 At Market","🔴 Above Market")),"-") -> ✅ Below Market | O5: =IF(L5="-","See opportunity analysis on dashboard",IF(L5<=I5*0.9,"Hold — Room to Increase Rate",IF(L5<=I5*1.1,"Hold — Well Positioned","Review Rate — Above Market"))) -> Hold — Room to Increase Rate | P5: ='Europcar rates'!G4 -> Dublin Airport | Economy (Small Car)
A6: Dublin Airport | B6: Economy (Small Car) | C6: Low Season Auto | D6: ='Competitor''s Rate'!B8 -> 37.142857 | E6: ='Competitor''s Rate'!C8 -> 37.142857 | F6: ='Competitor''s Rate'!D8 -> 126.71429 | G6: ='Competitor''s Rate'!E8 -> 30 | H6: ='Competitor''s Rate'!F8 -> 31 | I6: =IFERROR(AVERAGEIF(D6:H6,">"&0),"-") -> 52.4 | J6: =IFERROR(_xlfn.MINIFS(D6:H6,D6:H6,">"&0),"-") -> 30 | K6: =IFERROR(MAX(D6:H6),"-") -> 126.71429 | L6: =IFERROR(_xlfn.XLOOKUP(P6,'Europcar rates'!G:G,'Europcar rates'!D:D),"-") -> 35.428571 | M6: =IFERROR((L6-I6)/I6,"-") -> -0.32388222 | N6: =IFERROR(IF(L6<=I6*0.9,"✅ Below Market",IF(L6<=I6*1.1,"🟡 At Market","🔴 Above Market")),"-") -> ✅ Below Market | O6: =IF(L6="-","See opportunity analysis on dashboard",IF(L6<=I6*0.9,"Hold — Room to Increase Rate",IF(L6<=I6*1.1,"Hold — Well Positioned","Review Rate — Above Market"))) -> Hold — Room to Increase Rate | P6: ='Europcar rates'!G4 -> Dublin Airport | Economy (Small Car)
A7: Dublin Airport | B7: Economy (Small Car) | C7: High Season Manual | D7: ='Competitor''s Rate'!B9 -> 26.285714 | E7: ='Competitor''s Rate'!C9 -> 27.428571 | F7: ='Competitor''s Rate'!D9 -> 50 | G7: ='Competitor''s Rate'!E9 -> 21.428571 | H7: ='Competitor''s Rate'!F9 -> 32.571429 | I7: =IFERROR(AVERAGEIF(D7:H7,">"&0),"-") -> 31.542857 | J7: =IFERROR(_xlfn.MINIFS(D7:H7,D7:H7,">"&0),"-") -> 21.428571 | K7: =IFERROR(MAX(D7:H7),"-") -> 50 | L7: =IFERROR(_xlfn.XLOOKUP(P7,'Europcar rates'!G:G,'Europcar rates'!E:E),"-") -> 25.142857 | M7: =IFERROR((L7-I7)/I7,"-") -> -0.20289855 | N7: =IFERROR(IF(L7<=I7*0.9,"✅ Below Market",IF(L7<=I7*1.1,"🟡 At Market","🔴 Above Market")),"-") -> ✅ Below Market | O7: =IF(L7="-","See opportunity analysis on dashboard",IF(L7<=I7*0.9,"Hold — Room to Increase Rate",IF(L7<=I7*1.1,"Hold — Well Positioned","Review Rate — Above Market"))) -> Hold — Room to Increase Rate | P7: ='Europcar rates'!G4 -> Dublin Airport | Economy (Small Car)
A8: Dublin Airport | B8: Economy (Small Car) | C8: High Season Auto | D8: ='Competitor''s Rate'!B10 -> 45.428571 | E8: ='Competitor''s Rate'!C10 -> 45.285714 | F8: ='Competitor''s Rate'!D10 -> 112.42857 | G8: ='Competitor''s Rate'!E10 -> 37.571429 | H8: ='Competitor''s Rate'!F10 -> 39.571429 | I8: =IFERROR(AVERAGEIF(D8:H8,">"&0),"-") -> 56.057143 | J8: =IFERROR(_xlfn.MINIFS(D8:H8,D8:H8,">"&0),"-") -> 37.571429 | K8: =IFERROR(MAX(D8:H8),"-") -> 112.42857 | L8: =IFERROR(_xlfn.XLOOKUP(P8,'Europcar rates'!G:G,'Europcar rates'!F:F),"-") -> 43.285714 | M8: =IFERROR((L8-I8)/I8,"-") -> -0.22782875 | N8: =IFERROR(IF(L8<=I8*0.9,"✅ Below Market",IF(L8<=I8*1.1,"🟡 At Market","🔴 Above Market")),"-") -> ✅ Below Market | O8: =IF(L8="-","See opportunity analysis on dashboard",IF(L8<=I8*0.9,"Hold — Room to Increase Rate",IF(L8<=I8*1.1,"Hold — Well Positioned","Review Rate — Above Market"))) -> Hold — Room to Increase Rate | P8: ='Europcar rates'!G4 -> Dublin Airport | Economy (Small Car)
A9: Dublin Airport | B9: Compact (Medium Car) | C9: Low Season Manual | D9: ='Competitor''s Rate'!B13 -> 25 | E9: ='Competitor''s Rate'!C13 -> 25 | F9: ='Competitor''s Rate'!D13 -> 50.857143 | G9: ='Competitor''s Rate'!E13 -> 19 | H9: ='Competitor''s Rate'!F13 -> 21.857143 | I9: =IFERROR(AVERAGEIF(D9:H9,">"&0),"-") -> 28.342857 | J9: =IFERROR(_xlfn.MINIFS(D9:H9,D9:H9,">"&0),"-") -> 19 | K9: =IFERROR(MAX(D9:H9),"-") -> 50.857143 | L9: =IFERROR(_xlfn.XLOOKUP(P9,'Europcar rates'!G:G,'Europcar rates'!C:C),"-") -> 23.857143 | M9: =IFERROR((L9-I9)/I9,"-") -> -0.15826613 | N9: =IFERROR(IF(L9<=I9*0.9,"✅ Below Market",IF(L9<=I9*1.1,"🟡 At Market","🔴 Above Market")),"-") -> ✅ Below Market | O9: =IF(L9="-","See opportunity analysis on dashboard",IF(L9<=I9*0.9,"Hold — Room to Increase Rate",IF(L9<=I9*1.1,"Hold — Well Positioned","Review Rate — Above Market"))) -> Hold — Room to Increase Rate | P9: ='Europcar rates'!G5 -> Dublin Airport | Compact (Medium Car)
A10: Dublin Airport | B10: Compact (Medium Car) | C10: Low Season Auto | D10: ='Competitor''s Rate'!B14 -> 40 | E10: ='Competitor''s Rate'!C14 -> 40 | F10: ='Competitor''s Rate'!D14 -> 64 | G10: ='Competitor''s Rate'!E14 -> 32.857143 | H10: ='Competitor''s Rate'!F14 -> 34 | I10: =IFERROR(AVERAGEIF(D10:H10,">"&0),"-") -> 42.171429 | J10: =IFERROR(_xlfn.MINIFS(D10:H10,D10:H10,">"&0),"-") -> 32.857143 | K10: =IFERROR(MAX(D10:H10),"-") -> 64 | L10: =IFERROR(_xlfn.XLOOKUP(P10,'Europcar rates'!G:G,'Europcar rates'!D:D),"-") -> 38 | M10: =IFERROR((L10-I10)/I10,"-") -> -0.098915989 | N10: =IFERROR(IF(L10<=I10*0.9,"✅ Below Market",IF(L10<=I10*1.1,"🟡 At Market","🔴 Above Market")),"-") -> 🟡 At Market | O10: =IF(L10="-","See opportunity analysis on dashboard",IF(L10<=I10*0.9,"Hold — Room to Increase Rate",IF(L10<=I10*1.1,"Hold — Well Positioned","Review Rate — Above Market"))) -> Hold — Well Positioned | P10: Dublin Airport | Compact (Medium Car)
A11: Dublin Airport | B11: Compact (Medium Car) | C11: High Season Manual | D11: ='Competitor''s Rate'!B15 -> 28.571429 | E11: ='Competitor''s Rate'!C15 -> 28.428571 | F11: ='Competitor''s Rate'!D15 -> 67.571429 | G11: ='Competitor''s Rate'!E15 -> 24 | H11: ='Competitor''s Rate'!F15 -> 35.571429 | I11: =IFERROR(AVERAGEIF(D11:H11,">"&0),"-") -> 36.828571 | J11: =IFERROR(_xlfn.MINIFS(D11:H11,D11:H11,">"&0),"-") -> 24 | K11: =IFERROR(MAX(D11:H11),"-") -> 67.571429 | L11: =IFERROR(_xlfn.XLOOKUP(P11,'Europcar rates'!G:G,'Europcar rates'!E:E),"-") -> 27.142857 | M11: =IFERROR((L11-I11)/I11,"-") -> -0.26299457 | N11: =IFERROR(IF(L11<=I11*0.9,"✅ Below Market",IF(L11<=I11*1.1,"🟡 At Market","🔴 Above Market")),"-") -> ✅ Below Market | O11: =IF(L11="-","See opportunity analysis on dashboard",IF(L11<=I11*0.9,"Hold — Room to Increase Rate",IF(L11<=I11*1.1,"Hold — Well Positioned","Review Rate — Above Market"))) -> Hold — Room to Increase Rate | P11: Dublin Airport | Compact (Medium Car)
A12: Dublin Airport | B12: Compact (Medium Car) | C12: High Season Auto | D12: ='Competitor''s Rate'!B16 -> 49.285714 | E12: ='Competitor''s Rate'!C16 -> 49.285714 | F12: ='Competitor''s Rate'!D16 -> 82.714286 | G12: ='Competitor''s Rate'!E16 -> 50 | H12: ='Competitor''s Rate'!F16 -> 43.428571 | I12: =IFERROR(AVERAGEIF(D12:H12,">"&0),"-") -> 54.942857 | J12: =IFERROR(_xlfn.MINIFS(D12:H12,D12:H12,">"&0),"-") -> 43.428571 | K12: =IFERROR(MAX(D12:H12),"-") -> 82.714286 | L12: =IFERROR(_xlfn.XLOOKUP(P12,'Europcar rates'!G:G,'Europcar rates'!F:F),"-") -> 47 | M12: =IFERROR((L12-I12)/I12,"-") -> -0.14456578 | N12: =IFERROR(IF(L12<=I12*0.9,"✅ Below Market",IF(L12<=I12*1.1,"🟡 At Market","🔴 Above Market")),"-") -> ✅ Below Market | O12: =IF(L12="-","See opportunity analysis on dashboard",IF(L12<=I12*0.9,"Hold — Room to Increase Rate",IF(L12<=I12*1.1,"Hold — Well Positioned","Review Rate — Above Market"))) -> Hold — Room to Increase Rate | P12: Dublin Airport | Compact (Medium Car)
A13: Dublin Airport | B13: SUV | C13: Low Season Manual | D13: ='Competitor''s Rate'!B19 -> 26.428571 | E13: ='Competitor''s Rate'!C19 -> 26.428571 | F13: ='Competitor''s Rate'!D19 -> 53.714286 | G13: ='Competitor''s Rate'!E19 -> 24.142857 | H13: ='Competitor''s Rate'!F19 -> 22.142857 | I13: =IFERROR(AVERAGEIF(D13:H13,">"&0),"-") -> 30.571429 | J13: =IFERROR(_xlfn.MINIFS(D13:H13,D13:H13,">"&0),"-") -> 22.142857 | K13: =IFERROR(MAX(D13:H13),"-") -> 53.714286 | L13: =IFERROR(_xlfn.XLOOKUP(P13,'Europcar rates'!G:G,'Europcar rates'!C:C),"-") -> 29.571429 | M13: =IFERROR((L13-I13)/I13,"-") -> -0.03271028 | N13: =IFERROR(IF(L13<=I13*0.9,"✅ Below Market",IF(L13<=I13*1.1,"🟡 At Market","🔴 Above Market")),"-") -> 🟡 At Market | O13: =IF(L13="-","See opportunity analysis on dashboard",IF(L13<=I13*0.9,"Hold — Room to Increase Rate",IF(L13<=I13*1.1,"Hold — Well Positioned","Review Rate — Above Market"))) -> Hold — Well Positioned | P13: ='Europcar rates'!G6 -> Dublin Airport | SUV
A14: Dublin Airport | B14: SUV | C14: Low Season Auto | D14: ='Competitor''s Rate'!B20 -> 47.857143 | E14: ='Competitor''s Rate'!C20 -> 47.714286 | F14: ='Competitor''s Rate'!D20 -> 63.714286 | G14: ='Competitor''s Rate'!E20 -> 58.142857 | H14: ='Competitor''s Rate'!F20 -> 34.142857 | I14: =IFERROR(AVERAGEIF(D14:H14,">"&0),"-") -> 50.314286 | J14: =IFERROR(_xlfn.MINIFS(D14:H14,D14:H14,">"&0),"-") -> 34.142857 | K14: =IFERROR(MAX(D14:H14),"-") -> 63.714286 | L14: =IFERROR(_xlfn.XLOOKUP(P14,'Europcar rates'!G:G,'Europcar rates'!D:D),"-") -> 40 | M14: =IFERROR((L14-I14)/I14,"-") -> -0.20499716 | N14: =IFERROR(IF(L14<=I14*0.9,"✅ Below Market",IF(L14<=I14*1.1,"🟡 At Market","🔴 Above Market")),"-") -> ✅ Below Market | O14: =IF(L14="-","See opportunity analysis on dashboard",IF(L14<=I14*0.9,"Hold — Room to Increase Rate",IF(L14<=I14*1.1,"Hold — Well Positioned","Review Rate — Above Market"))) -> Hold — Room to Increase Rate | P14: Dublin Airport | SUV
A15: Dublin Airport | B15: SUV | C15: High Season Manual | D15: ='Competitor''s Rate'!B21 -> 30 | E15: ='Competitor''s Rate'!C21 -> 29.857143 | F15: ='Competitor''s Rate'!D21 -> 69.571429 | G15: ='Competitor''s Rate'!E21 -> 30.857143 | H15: ='Competitor''s Rate'!F21 -> 36.142857 | I15: =IFERROR(AVERAGEIF(D15:H15,">"&0),"-") -> 39.285714 | J15: =IFERROR(_xlfn.MINIFS(D15:H15,D15:H15,">"&0),"-") -> 29.857143 | K15: =IFERROR(MAX(D15:H15),"-") -> 69.571429 | L15: =IFERROR(_xlfn.XLOOKUP(P15,'Europcar rates'!G:G,'Europcar rates'!E:E),"-") -> 32.428571 | M15: =IFERROR((L15-I15)/I15,"-") -> -0.17454545 | N15: =IFERROR(IF(L15<=I15*0.9,"✅ Below Market",IF(L15<=I15*1.1,"🟡 At Market","🔴 Above Market")),"-") -> ✅ Below Market | O15: =IF(L15="-","See opportunity analysis on dashboard",IF(L15<=I15*0.9,"Hold — Room to Increase Rate",IF(L15<=I15*1.1,"Hold — Well Positioned","Review Rate — Above Market"))) -> Hold — Room to Increase Rate | P15: Dublin Airport | SUV
A16: Dublin Airport | B16: SUV | C16: High Season Auto | D16: ='Competitor''s Rate'!B22 -> 57.857143 | E16: ='Competitor''s Rate'!C22 -> 57.857143 | F16: ='Competitor''s Rate'!D22 -> 82.714286 | G16: ='Competitor''s Rate'!E22 -> 65.142857 | H16: ='Competitor''s Rate'!F22 -> 43.571429 | I16: =IFERROR(AVERAGEIF(D16:H16,">"&0),"-") -> 61.428571 | J16: =IFERROR(_xlfn.MINIFS(D16:H16,D16:H16,">"&0),"-") -> 43.571429 | K16: =IFERROR(MAX(D16:H16),"-") -> 82.714286 | L16: =IFERROR(_xlfn.XLOOKUP(P16,'Europcar rates'!G:G,'Europcar rates'!F:F),"-") -> 55 | M16: =IFERROR((L16-I16)/I16,"-") -> -0.10465116 | N16: =IFERROR(IF(L16<=I16*0.9,"✅ Below Market",IF(L16<=I16*1.1,"🟡 At Market","🔴 Above Market")),"-") -> ✅ Below Market | O16: =IF(L16="-","See opportunity analysis on dashboard",IF(L16<=I16*0.9,"Hold — Room to Increase Rate",IF(L16<=I16*1.1,"Hold — Well Positioned","Review Rate — Above Market"))) -> Hold — Room to Increase Rate | P16: Dublin Airport | SUV
A17: Dublin Airport | B17: People Carrier | C17: Low Season Manual | D17: ='Competitor''s Rate'!B25 -> - | E17: ='Competitor''s Rate'!C25 -> 192.85714 | F17: ='Competitor''s Rate'!D25 -> - | G17: ='Competitor''s Rate'!E25 -> 104.28571 | H17: ='Competitor''s Rate'!F25 -> - | I17: =IFERROR(AVERAGEIF(D17:H17,">"&0),"-") -> 148.57143 | J17: =IFERROR(_xlfn.MINIFS(D17:H17,D17:H17,">"&0),"-") -> 104.28571 | K17: =IFERROR(MAX(D17:H17),"-") -> 192.85714 | L17: =IFERROR(_xlfn.XLOOKUP(P17,'Europcar rates'!G:G,'Europcar rates'!C:C),"-") -> - | M17: =IFERROR((L17-I17)/I17,"-") -> - | N17: =IF(L17="-","⚪ Not Offered by Europcar",IF(L17<=I17*0.9,"✅ Below Market",IF(L17<=I17*1.1,"🟡 At Market","🔴 Above Market"))) -> ⚪ Not Offered by Europcar | O17: =IF(L17="-","See opportunity analysis on dashboard",IF(L17<=I17*0.9,"Hold — Room to Increase Rate",IF(L17<=I17*1.1,"Hold — Well Positioned","Review Rate — Above Market"))) -> See opportunity analysis on dashboard | P17: ='Europcar rates'!G7 -> Dublin Airport | People carrier
A18: Dublin Airport | B18: People Carrier | C18: Low Season Auto | D18: ='Competitor''s Rate'!B26 -> 555 | E18: ='Competitor''s Rate'!C26 -> 221.42857 | F18: ='Competitor''s Rate'!D26 -> 147.71429 | G18: ='Competitor''s Rate'!E26 -> 430.42857 | H18: ='Competitor''s Rate'!F26 -> 258.14286 | I18: =IFERROR(AVERAGEIF(D18:H18,">"&0),"-") -> 322.54286 | J18: =IFERROR(_xlfn.MINIFS(D18:H18,D18:H18,">"&0),"-") -> 147.71429 | K18: =IFERROR(MAX(D18:H18),"-") -> 555 | L18: =IFERROR(_xlfn.XLOOKUP(P18,'Europcar rates'!G:G,'Europcar rates'!D:D),"-") -> 85.142857 | M18: =IFERROR((L18-I18)/I18,"-") -> -0.73602622 | N18: =IF(L18="-","⚪ Not Offered by Europcar",IF(L18<=I18*0.9,"✅ Below Market",IF(L18<=I18*1.1,"🟡 At Market","🔴 Above Market"))) -> ✅ Below Market | O18: =IF(L18="-","See opportunity analysis on dashboard",IF(L18<=I18*0.9,"Hold — Room to Increase Rate",IF(L18<=I18*1.1,"Hold — Well Positioned","Review Rate — Above Market"))) -> Hold — Room to Increase Rate | P18: Dublin Airport | People carrier
A19: Dublin Airport | B19: People Carrier | C19: High Season Manual | D19: ='Competitor''s Rate'!B27 -> - | E19: ='Competitor''s Rate'!C27 -> 243.28571 | F19: ='Competitor''s Rate'!D27 -> - | G19: ='Competitor''s Rate'!E27 -> 92 | H19: ='Competitor''s Rate'!F27 -> 339.14286 | I19: =IFERROR(AVERAGEIF(D19:H19,">"&0),"-") -> 224.80952 | J19: =IFERROR(_xlfn.MINIFS(D19:H19,D19:H19,">"&0),"-") -> 92 | K19: =IFERROR(MAX(D19:H19),"-") -> 339.14286 | L19: =IFERROR(_xlfn.XLOOKUP(P19,'Europcar rates'!G:G,'Europcar rates'!E:E),"-") -> - | M19: =IFERROR((L19-I19)/I19,"-") -> - | N19: =IF(L19="-","⚪ Not Offered by Europcar",IF(L19<=I19*0.9,"✅ Below Market",IF(L19<=I19*1.1,"🟡 At Market","🔴 Above Market"))) -> ⚪ Not Offered by Europcar | O19: =IF(L19="-","See opportunity analysis on dashboard",IF(L19<=I19*0.9,"Hold — Room to Increase Rate",IF(L19<=I19*1.1,"Hold — Well Positioned","Review Rate — Above Market"))) -> See opportunity analysis on dashboard | P19: Dublin Airport | People carrier
A20: Dublin Airport | B20: People Carrier | C20: High Season Auto | D20: ='Competitor''s Rate'!B28 -> 300 | E20: ='Competitor''s Rate'!C28 -> 290.28571 | F20: ='Competitor''s Rate'!D28 -> 191.42857 | G20: ='Competitor''s Rate'!E28 -> 208.71429 | H20: ='Competitor''s Rate'!F28 -> - | I20: =IFERROR(AVERAGEIF(D20:H20,">"&0),"-") -> 247.60714 | J20: =IFERROR(_xlfn.MINIFS(D20:H20,D20:H20,">"&0),"-") -> 191.42857 | K20: =IFERROR(MAX(D20:H20),"-") -> 300 | L20: =IFERROR(_xlfn.XLOOKUP(P20,'Europcar rates'!G:G,'Europcar rates'!F:F),"-") -> 94.857143 | M20: =IFERROR((L20-I20)/I20,"-") -> -0.61690466 | N20: =IF(L20="-","⚪ Not Offered by Europcar",IF(L20<=I20*0.9,"✅ Below Market",IF(L20<=I20*1.1,"🟡 At Market","🔴 Above Market"))) -> ✅ Below Market | O20: =IF(L20="-","See opportunity analysis on dashboard",IF(L20<=I20*0.9,"Hold — Room to Increase Rate",IF(L20<=I20*1.1,"Hold — Well Positioned","Review Rate — Above Market"))) -> Hold — Room to Increase Rate | P20: Dublin Airport | People carrier
A21: Cork Airport | B21: Economy (Small Car) | C21: Low Season Manual | D21: ='Competitor''s Rate'!H7 -> 22.857143 | E21: ='Competitor''s Rate'!I7 -> 23.571429 | F21: ='Competitor''s Rate'!J7 -> 52.857143 | G21: ='Competitor''s Rate'!K7 -> 16.571429 | H21: ='Competitor''s Rate'!L7 -> 20 | I21: =IFERROR(AVERAGEIF(D21:H21,">"&0),"-") -> 27.171429 | J21: =IFERROR(_xlfn.MINIFS(D21:H21,D21:H21,">"&0),"-") -> 16.571429 | K21: =IFERROR(MAX(D21:H21),"-") -> 52.857143 | L21: =IFERROR(_xlfn.XLOOKUP(P21,'Europcar rates'!G:G,'Europcar rates'!C:C),"-") -> 21.142857 | M21: =IFERROR((L21-I21)/I21,"-") -> -0.22187171 | N21: =IF(L21="-","⚪ Not Offered by Europcar",IF(L21<=I21*0.9,"✅ Below Market",IF(L21<=I21*1.1,"🟡 At Market","🔴 Above Market"))) -> ✅ Below Market | O21: =IF(L21="-","See opportunity analysis on dashboard",IF(L21<=I21*0.9,"Hold — Room to Increase Rate",IF(L21<=I21*1.1,"Hold — Well Positioned","Review Rate — Above Market"))) -> Hold — Room to Increase Rate | P21: ='Europcar rates'!G9 -> Cork Airport | Economy (Small Car)
A22: Cork Airport | B22: Economy (Small Car) | C22: Low Season Auto | D22: ='Competitor''s Rate'!H8 -> 37.142857 | E22: ='Competitor''s Rate'!I8 -> 39.142857 | F22: ='Competitor''s Rate'!J8 -> 72.857143 | G22: ='Competitor''s Rate'!K8 -> 30 | H22: ='Competitor''s Rate'!L8 -> 31 | I22: =IFERROR(AVERAGEIF(D22:H22,">"&0),"-") -> 42.028571 | J22: =IFERROR(_xlfn.MINIFS(D22:H22,D22:H22,">"&0),"-") -> 30 | K22: =IFERROR(MAX(D22:H22),"-") -> 72.857143 | L22: =IFERROR(_xlfn.XLOOKUP(P22,'Europcar rates'!G:G,'Europcar rates'!D:D),"-") -> 35.428571 | M22: =IFERROR((L22-I22)/I22,"-") -> -0.15703603 | N22: =IF(L22="-","⚪ Not Offered by Europcar",IF(L22<=I22*0.9,"✅ Below Market",IF(L22<=I22*1.1,"🟡 At Market","🔴 Above Market"))) -> ✅ Below Market | O22: =IF(L22="-","See opportunity analysis on dashboard",IF(L22<=I22*0.9,"Hold — Room to Increase Rate",IF(L22<=I22*1.1,"Hold — Well Positioned","Review Rate — Above Market"))) -> Hold — Room to Increase Rate | P22: Cork Airport | Economy (Small Car)
A23: Cork Airport | B23: Economy (Small Car) | C23: High Season Manual | D23: ='Competitor''s Rate'!H9 -> 26.285714 | E23: ='Competitor''s Rate'!I9 -> 27.428571 | F23: ='Competitor''s Rate'!J9 -> 71.428571 | G23: ='Competitor''s Rate'!K9 -> 21.428571 | H23: ='Competitor''s Rate'!L9 -> 23.142857 | I23: =IFERROR(AVERAGEIF(D23:H23,">"&0),"-") -> 33.942857 | J23: =IFERROR(_xlfn.MINIFS(D23:H23,D23:H23,">"&0),"-") -> 21.428571 | K23: =IFERROR(MAX(D23:H23),"-") -> 71.428571 | L23: =IFERROR(_xlfn.XLOOKUP(P23,'Europcar rates'!G:G,'Europcar rates'!E:E),"-") -> 25.142857 | M23: =IFERROR((L23-I23)/I23,"-") -> -0.25925926 | N23: =IF(L23="-","⚪ Not Offered by Europcar",IF(L23<=I23*0.9,"✅ Below Market",IF(L23<=I23*1.1,"🟡 At Market","🔴 Above Market"))) -> ✅ Below Market | O23: =IF(L23="-","See opportunity analysis on dashboard",IF(L23<=I23*0.9,"Hold — Room to Increase Rate",IF(L23<=I23*1.1,"Hold — Well Positioned","Review Rate — Above Market"))) -> Hold — Room to Increase Rate | P23: Cork Airport | Economy (Small Car)
A24: Cork Airport | B24: Economy (Small Car) | C24: High Season Auto | D24: ='Competitor''s Rate'!H10 -> 45.428571 | E24: ='Competitor''s Rate'!I10 -> 45.285714 | F24: ='Competitor''s Rate'!J10 -> 110.85714 | G24: ='Competitor''s Rate'!K10 -> 37.571429 | H24: ='Competitor''s Rate'!L10 -> 37.714286 | I24: =IFERROR(AVERAGEIF(D24:H24,">"&0),"-") -> 55.371429 | J24: =IFERROR(_xlfn.MINIFS(D24:H24,D24:H24,">"&0),"-") -> 37.571429 | K24: =IFERROR(MAX(D24:H24),"-") -> 110.85714 | L24: =IFERROR(_xlfn.XLOOKUP(P24,'Europcar rates'!G:G,'Europcar rates'!F:F),"-") -> 43.285714 | M24: =IFERROR((L24-I24)/I24,"-") -> -0.21826625 | N24: =IF(L24="-","⚪ Not Offered by Europcar",IF(L24<=I24*0.9,"✅ Below Market",IF(L24<=I24*1.1,"🟡 At Market","🔴 Above Market"))) -> ✅ Below Market | O24: =IF(L24="-","See opportunity analysis on dashboard",IF(L24<=I24*0.9,"Hold — Room to Increase Rate",IF(L24<=I24*1.1,"Hold — Well Positioned","Review Rate — Above Market"))) -> Hold — Room to Increase Rate | P24: Cork Airport | Economy (Small Car)
A25: Cork Airport | B25: Economy (Small Car) | C25: Low Season Manual | D25: ='Competitor''s Rate'!H13 -> 25 | E25: ='Competitor''s Rate'!I13 -> 25.714286 | F25: ='Competitor''s Rate'!J13 -> 58.428571 | G25: ='Competitor''s Rate'!K13 -> 19 | H25: ='Competitor''s Rate'!L13 -> 21.857143 | I25: =IFERROR(AVERAGEIF(D25:H25,">"&0),"-") -> 30 | J25: =IFERROR(_xlfn.MINIFS(D25:H25,D25:H25,">"&0),"-") -> 19 | K25: =IFERROR(MAX(D25:H25),"-") -> 58.428571 | L25: =IFERROR(_xlfn.XLOOKUP(P25,'Europcar rates'!G:G,'Europcar rates'!C:C),"-") -> 23.857143 | M25: =IFERROR((L25-I25)/I25,"-") -> -0.2047619 | N25: =IF(L25="-","⚪ Not Offered by Europcar",IF(L25<=I25*0.9,"✅ Below Market",IF(L25<=I25*1.1,"🟡 At Market","🔴 Above Market"))) -> ✅ Below Market | O25: =IF(L25="-","See opportunity analysis on dashboard",IF(L25<=I25*0.9,"Hold — Room to Increase Rate",IF(L25<=I25*1.1,"Hold — Well Positioned","Review Rate — Above Market"))) -> Hold — Room to Increase Rate | P25: ='Europcar rates'!G10 -> Cork Airport | Compact (Medium Car)
A26: Cork Airport | B26: Compact (Medium Car) | C26: Low Season Auto | D26: ='Competitor''s Rate'!H14 -> 40 | E26: ='Competitor''s Rate'!I14 -> 42 | F26: ='Competitor''s Rate'!J14 -> 82.857143 | G26: ='Competitor''s Rate'!K14 -> 32.857143 | H26: ='Competitor''s Rate'!L14 -> 34 | I26: =IFERROR(AVERAGEIF(D26:H26,">"&0),"-") -> 46.342857 | J26: =IFERROR(_xlfn.MINIFS(D26:H26,D26:H26,">"&0),"-") -> 32.857143 | K26: =IFERROR(MAX(D26:H26),"-") -> 82.857143 | L26: =IFERROR(_xlfn.XLOOKUP(P26,'Europcar rates'!G:G,'Europcar rates'!D:D),"-") -> 38 | M26: =IFERROR((L26-I26)/I26,"-") -> -0.18002466 | N26: =IF(L26="-","⚪ Not Offered by Europcar",IF(L26<=I26*0.9,"✅ Below Market",IF(L26<=I26*1.1,"🟡 At Market","🔴 Above Market"))) -> ✅ Below Market | O26: =IF(L26="-","See opportunity analysis on dashboard",IF(L26<=I26*0.9,"Hold — Room to Increase Rate",IF(L26<=I26*1.1,"Hold — Well Positioned","Review Rate — Above Market"))) -> Hold — Room to Increase Rate | P26: Cork Airport | Compact (Medium Car)
A27: Cork Airport | B27: Compact (Medium Car) | C27: High Season Manual | D27: ='Competitor''s Rate'!H15 -> 28.571429 | E27: ='Competitor''s Rate'!I15 -> 28.428571 | F27: ='Competitor''s Rate'!J15 -> 78.571429 | G27: ='Competitor''s Rate'!K15 -> 24 | H27: ='Competitor''s Rate'!L15 -> 25.285714 | I27: =IFERROR(AVERAGEIF(D27:H27,">"&0),"-") -> 36.971429 | J27: =IFERROR(_xlfn.MINIFS(D27:H27,D27:H27,">"&0),"-") -> 24 | K27: =IFERROR(MAX(D27:H27),"-") -> 78.571429 | L27: =IFERROR(_xlfn.XLOOKUP(P27,'Europcar rates'!G:G,'Europcar rates'!E:E),"-") -> 27.142857 | M27: =IFERROR((L27-I27)/I27,"-") -> -0.26584235 | N27: =IF(L27="-","⚪ Not Offered by Europcar",IF(L27<=I27*0.9,"✅ Below Market",IF(L27<=I27*1.1,"🟡 At Market","🔴 Above Market"))) -> ✅ Below Market | O27: =IF(L27="-","See opportunity analysis on dashboard",IF(L27<=I27*0.9,"Hold — Room to Increase Rate",IF(L27<=I27*1.1,"Hold — Well Positioned","Review Rate — Above Market"))) -> Hold — Room to Increase Rate | P27: Cork Airport | Compact (Medium Car)
A28: Cork Airport | B28: Compact (Medium Car) | C28: High Season Auto | D28: ='Competitor''s Rate'!H16 -> 49.285714 | E28: ='Competitor''s Rate'!I16 -> 49.285714 | F28: ='Competitor''s Rate'!J16 -> 117.28571 | G28: ='Competitor''s Rate'!K16 -> 50 | H28: ='Competitor''s Rate'!L16 -> 41.428571 | I28: =IFERROR(AVERAGEIF(D28:H28,">"&0),"-") -> 61.457143 | J28: =IFERROR(_xlfn.MINIFS(D28:H28,D28:H28,">"&0),"-") -> 41.428571 | K28: =IFERROR(MAX(D28:H28),"-") -> 117.28571 | L28: =IFERROR(_xlfn.XLOOKUP(P28,'Europcar rates'!G:G,'Europcar rates'!F:F),"-") -> 47 | M28: =IFERROR((L28-I28)/I28,"-") -> -0.23523942 | N28: =IF(L28="-","⚪ Not Offered by Europcar",IF(L28<=I28*0.9,"✅ Below Market",IF(L28<=I28*1.1,"🟡 At Market","🔴 Above Market"))) -> ✅ Below Market | O28: =IF(L28="-","See opportunity analysis on dashboard",IF(L28<=I28*0.9,"Hold — Room to Increase Rate",IF(L28<=I28*1.1,"Hold — Well Positioned","Review Rate — Above Market"))) -> Hold — Room to Increase Rate | P28: Cork Airport | Compact (Medium Car)
A29: Cork Airport | B29: SUV | C29: Low Season Manual | D29: ='Competitor''s Rate'!H19 -> 26.428571 | E29: ='Competitor''s Rate'!I19 -> 27.142857 | F29: ='Competitor''s Rate'!J19 -> 61.285714 | G29: ='Competitor''s Rate'!K19 -> 24.142857 | H29: ='Competitor''s Rate'!L19 -> 22.142857 | I29: =IFERROR(AVERAGEIF(D29:H29,">"&0),"-") -> 32.228571 | J29: =IFERROR(_xlfn.MINIFS(D29:H29,D29:H29,">"&0),"-") -> 22.142857 | K29: =IFERROR(MAX(D29:H29),"-") -> 61.285714 | L29: =IFERROR(_xlfn.XLOOKUP(P29,'Europcar rates'!G:G,'Europcar rates'!C:C),"-") -> 29.571429 | M29: =IFERROR((L29-I29)/I29,"-") -> -0.082446809 | N29: =IF(L29="-","⚪ Not Offered by Europcar",IF(L29<=I29*0.9,"✅ Below Market",IF(L29<=I29*1.1,"🟡 At Market","🔴 Above Market"))) -> 🟡 At Market | O29: =IF(L29="-","See opportunity analysis on dashboard",IF(L29<=I29*0.9,"Hold — Room to Increase Rate",IF(L29<=I29*1.1,"Hold — Well Positioned","Review Rate — Above Market"))) -> Hold — Well Positioned | P29: ='Europcar rates'!G11 -> Cork Airport | SUV
A30: Cork Airport | B30: SUV | C30: Low Season Auto | D30: ='Competitor''s Rate'!H20 -> 47.857143 | E30: ='Competitor''s Rate'!I20 -> 51.285714 | F30: ='Competitor''s Rate'!J20 -> 87.428571 | G30: ='Competitor''s Rate'!K20 -> 58.142857 | H30: ='Competitor''s Rate'!L20 -> 34.142857 | I30: =IFERROR(AVERAGEIF(D30:H30,">"&0),"-") -> 55.771429 | J30: =IFERROR(_xlfn.MINIFS(D30:H30,D30:H30,">"&0),"-") -> 34.142857 | K30: =IFERROR(MAX(D30:H30),"-") -> 87.428571 | L30: =IFERROR(_xlfn.XLOOKUP(P30,'Europcar rates'!G:G,'Europcar rates'!D:D),"-") -> 45.142857 | M30: =IFERROR((L30-I30)/I30,"-") -> -0.19057377 | N30: =IF(L30="-","⚪ Not Offered by Europcar",IF(L30<=I30*0.9,"✅ Below Market",IF(L30<=I30*1.1,"🟡 At Market","🔴 Above Market"))) -> ✅ Below Market | O30: =IF(L30="-","See opportunity analysis on dashboard",IF(L30<=I30*0.9,"Hold — Room to Increase Rate",IF(L30<=I30*1.1,"Hold — Well Positioned","Review Rate — Above Market"))) -> Hold — Room to Increase Rate | P30: Cork Airport | SUV
A31: Cork Airport | B31: SUV | C31: High Season Manual | D31: ='Competitor''s Rate'!H21 -> 30 | E31: ='Competitor''s Rate'!I21 -> 29.857143 | F31: ='Competitor''s Rate'!J21 -> 82.428571 | G31: ='Competitor''s Rate'!K21 -> 30.857143 | H31: ='Competitor''s Rate'!L21 -> 27 | I31: =IFERROR(AVERAGEIF(D31:H31,">"&0),"-") -> 40.028571 | J31: =IFERROR(_xlfn.MINIFS(D31:H31,D31:H31,">"&0),"-") -> 27 | K31: =IFERROR(MAX(D31:H31),"-") -> 82.428571 | L31: =IFERROR(_xlfn.XLOOKUP(P31,'Europcar rates'!G:G,'Europcar rates'!E:E),"-") -> 32.428571 | M31: =IFERROR((L31-I31)/I31,"-") -> -0.18986438 | N31: =IF(L31="-","⚪ Not Offered by Europcar",IF(L31<=I31*0.9,"✅ Below Market",IF(L31<=I31*1.1,"🟡 At Market","🔴 Above Market"))) -> ✅ Below Market | O31: =IF(L31="-","See opportunity analysis on dashboard",IF(L31<=I31*0.9,"Hold — Room to Increase Rate",IF(L31<=I31*1.1,"Hold — Well Positioned","Review Rate — Above Market"))) -> Hold — Room to Increase Rate | P31: Cork Airport | SUV
A32: Cork Airport | B32: SUV | C32: High Season Auto | D32: ='Competitor''s Rate'!H22 -> 57.857143 | E32: ='Competitor''s Rate'!I22 -> 57.857143 | F32: ='Competitor''s Rate'!J22 -> 122.14286 | G32: ='Competitor''s Rate'!K22 -> 65.142857 | H32: ='Competitor''s Rate'!L22 -> 43.571429 | I32: =IFERROR(AVERAGEIF(D32:H32,">"&0),"-") -> 69.314286 | J32: =IFERROR(_xlfn.MINIFS(D32:H32,D32:H32,">"&0),"-") -> 43.571429 | K32: =IFERROR(MAX(D32:H32),"-") -> 122.14286 | L32: =IFERROR(_xlfn.XLOOKUP(P32,'Europcar rates'!G:G,'Europcar rates'!F:F),"-") -> 55 | M32: =IFERROR((L32-I32)/I32,"-") -> -0.20651278 | N32: =IF(L32="-","⚪ Not Offered by Europcar",IF(L32<=I32*0.9,"✅ Below Market",IF(L32<=I32*1.1,"🟡 At Market","🔴 Above Market"))) -> ✅ Below Market | O32: =IF(L32="-","See opportunity analysis on dashboard",IF(L32<=I32*0.9,"Hold — Room to Increase Rate",IF(L32<=I32*1.1,"Hold — Well Positioned","Review Rate — Above Market"))) -> Hold — Room to Increase Rate | P32: Cork Airport | SUV
A33: Cork Airport | B33: People Carrier | C33: Low Season Manual | D33: ='Competitor''s Rate'!H25 -> - | E33: ='Competitor''s Rate'!I25 -> 192.85714 | F33: ='Competitor''s Rate'!J25 -> - | G33: ='Competitor''s Rate'!K25 -> 104.28571 | H33: ='Competitor''s Rate'!L25 -> - | I33: =IFERROR(AVERAGEIF(D33:H33,">"&0),"-") -> 148.57143 | J33: =IFERROR(_xlfn.MINIFS(D33:H33,D33:H33,">"&0),"-") -> 104.28571 | K33: =IFERROR(MAX(D33:H33),"-") -> 192.85714 | L33: =IFERROR(_xlfn.XLOOKUP(P33,'Europcar rates'!G:G,'Europcar rates'!C:C),"-") -> - | M33: =IFERROR((L33-I33)/I33,"-") -> - | N33: =IF(L33="-","⚪ Not Offered by Europcar",IF(L33<=I33*0.9,"✅ Below Market",IF(L33<=I33*1.1,"🟡 At Market","🔴 Above Market"))) -> ⚪ Not Offered by Europcar | O33: =IF(L33="-","See opportunity analysis on dashboard",IF(L33<=I33*0.9,"Hold — Room to Increase Rate",IF(L33<=I33*1.1,"Hold — Well Positioned","Review Rate — Above Market"))) -> See opportunity analysis on dashboard | P33: ='Europcar rates'!G12 -> Cork Airport | People carrier
A34: Cork Airport | B34: People Carrier | C34: Low Season Auto | D34: ='Competitor''s Rate'!H26 -> 555 | E34: ='Competitor''s Rate'!I26 -> 221.42857 | F34: ='Competitor''s Rate'!J26 -> 179.42857 | G34: ='Competitor''s Rate'!K26 -> 430.42857 | H34: ='Competitor''s Rate'!L26 -> - | I34: =IFERROR(AVERAGEIF(D34:H34,">"&0),"-") -> 346.57143 | J34: =IFERROR(_xlfn.MINIFS(D34:H34,D34:H34,">"&0),"-") -> 179.42857 | K34: =IFERROR(MAX(D34:H34),"-") -> 555 | L34: =IFERROR(_xlfn.XLOOKUP(P34,'Europcar rates'!G:G,'Europcar rates'!D:D),"-") -> - | M34: =IFERROR((L34-I34)/I34,"-") -> - | N34: =IF(L34="-","⚪ Not Offered by Europcar",IF(L34<=I34*0.9,"✅ Below Market",IF(L34<=I34*1.1,"🟡 At Market","🔴 Above Market"))) -> ⚪ Not Offered by Europcar | O34: =IF(L34="-","See opportunity analysis on dashboard",IF(L34<=I34*0.9,"Hold — Room to Increase Rate",IF(L34<=I34*1.1,"Hold — Well Positioned","Review Rate — Above Market"))) -> See opportunity analysis on dashboard | P34: Cork Airport | People carrier
A35: Cork Airport | B35: People Carrier | C35: High Season Manual | D35: ='Competitor''s Rate'!H27 -> - | E35: ='Competitor''s Rate'!I27 -> 243.28571 | F35: ='Competitor''s Rate'!J27 -> - | G35: ='Competitor''s Rate'!K27 -> 92 | H35: ='Competitor''s Rate'!L27 -> - | I35: =IFERROR(AVERAGEIF(D35:H35,">"&0),"-") -> 167.64286 | J35: =IFERROR(_xlfn.MINIFS(D35:H35,D35:H35,">"&0),"-") -> 92 | K35: =IFERROR(MAX(D35:H35),"-") -> 243.28571 | L35: =IFERROR(_xlfn.XLOOKUP(P35,'Europcar rates'!G:G,'Europcar rates'!E:E),"-") -> - | M35: =IFERROR((L35-I35)/I35,"-") -> - | N35: =IF(L35="-","⚪ Not Offered by Europcar",IF(L35<=I35*0.9,"✅ Below Market",IF(L35<=I35*1.1,"🟡 At Market","🔴 Above Market"))) -> ⚪ Not Offered by Europcar | O35: =IF(L35="-","See opportunity analysis on dashboard",IF(L35<=I35*0.9,"Hold — Room to Increase Rate",IF(L35<=I35*1.1,"Hold — Well Positioned","Review Rate — Above Market"))) -> See opportunity analysis on dashboard | P35: Cork Airport | People carrier
A36: Cork Airport | B36: People Carrier | C36: High Season Auto | D36: ='Competitor''s Rate'!H28 -> 300 | E36: ='Competitor''s Rate'!I28 -> 290.28571 | F36: ='Competitor''s Rate'!J28 -> 192.85714 | G36: ='Competitor''s Rate'!K28 -> 208.71429 | H36: ='Competitor''s Rate'!L28 -> - | I36: =IFERROR(AVERAGEIF(D36:H36,">"&0),"-") -> 247.96429 | J36: =IFERROR(_xlfn.MINIFS(D36:H36,D36:H36,">"&0),"-") -> 192.85714 | K36: =IFERROR(MAX(D36:H36),"-") -> 300 | L36: =IFERROR(_xlfn.XLOOKUP(P36,'Europcar rates'!G:G,'Europcar rates'!F:F),"-") -> - | M36: =IFERROR((L36-I36)/I36,"-") -> - | N36: =IF(L36="-","⚪ Not Offered by Europcar",IF(L36<=I36*0.9,"✅ Below Market",IF(L36<=I36*1.1,"🟡 At Market","🔴 Above Market"))) -> ⚪ Not Offered by Europcar | O36: =IF(L36="-","See opportunity analysis on dashboard",IF(L36<=I36*0.9,"Hold — Room to Increase Rate",IF(L36<=I36*1.1,"Hold — Well Positioned","Review Rate — Above Market"))) -> See opportunity analysis on dashboard | P36: Cork Airport | People carrier
A37: Shannon Airport | B37: Economy (Small Car) | C37: Low Season Manual | D37: ='Competitor''s Rate'!N7 -> 22.142857 | E37: ='Competitor''s Rate'!O7 -> 23.571429 | F37: ='Competitor''s Rate'!P7 -> 52.857143 | G37: ='Competitor''s Rate'!Q7 -> 16.142857 | H37: ='Competitor''s Rate'!R7 -> 32.571429 | I37: =IFERROR(AVERAGEIF(D37:H37,">"&0),"-") -> 29.457143 | J37: =IFERROR(_xlfn.MINIFS(D37:H37,D37:H37,">"&0),"-") -> 16.142857 | K37: =IFERROR(MAX(D37:H37),"-") -> 52.857143 | L37: =IFERROR(_xlfn.XLOOKUP(P37,'Europcar rates'!G:G,'Europcar rates'!C:C),"-") -> 21.142857 | M37: =IFERROR((L37-I37)/I37,"-") -> -0.28225024 | N37: =IF(L37="-","⚪ Not Offered by Europcar",IF(L37<=I37*0.9,"✅ Below Market",IF(L37<=I37*1.1,"🟡 At Market","🔴 Above Market"))) -> ✅ Below Market | O37: =IF(L37="-","See opportunity analysis on dashboard",IF(L37<=I37*0.9,"Hold — Room to Increase Rate",IF(L37<=I37*1.1,"Hold — Well Positioned","Review Rate — Above Market"))) -> Hold — Room to Increase Rate | P37: ='Europcar rates'!G14 -> Shannon Airport | Economy (Small Car)
A38: Shannon Airport | B38: Economy (Small Car) | C38: Low Season Auto | D38: ='Competitor''s Rate'!N8 -> 37.142857 | E38: ='Competitor''s Rate'!O8 -> 39.142857 | F38: ='Competitor''s Rate'!P8 -> 68.714286 | G38: ='Competitor''s Rate'!Q8 -> 30 | H38: ='Competitor''s Rate'!R8 -> 39.571429 | I38: =IFERROR(AVERAGEIF(D38:H38,">"&0),"-") -> 42.914286 | J38: =IFERROR(_xlfn.MINIFS(D38:H38,D38:H38,">"&0),"-") -> 30 | K38: =IFERROR(MAX(D38:H38),"-") -> 68.714286 | L38: =IFERROR(_xlfn.XLOOKUP(P38,'Europcar rates'!G:G,'Europcar rates'!D:D),"-") -> 35.428571 | M38: =IFERROR((L38-I38)/I38,"-") -> -0.17443409 | N38: =IF(L38="-","⚪ Not Offered by Europcar",IF(L38<=I38*0.9,"✅ Below Market",IF(L38<=I38*1.1,"🟡 At Market","🔴 Above Market"))) -> ✅ Below Market | O38: =IF(L38="-","See opportunity analysis on dashboard",IF(L38<=I38*0.9,"Hold — Room to Increase Rate",IF(L38<=I38*1.1,"Hold — Well Positioned","Review Rate — Above Market"))) -> Hold — Room to Increase Rate | P38: Shannon Airport | Economy (Small Car)
A39: Shannon Airport | B39: Economy (Small Car) | C39: High Season Manual | D39: ='Competitor''s Rate'!N9 -> 26.285714 | E39: ='Competitor''s Rate'!O9 -> 27.428571 | F39: ='Competitor''s Rate'!P9 -> 52.857143 | G39: ='Competitor''s Rate'!Q9 -> 21.428571 | H39: ='Competitor''s Rate'!R9 -> 23.142857 | I39: =IFERROR(AVERAGEIF(D39:H39,">"&0),"-") -> 30.228571 | J39: =IFERROR(_xlfn.MINIFS(D39:H39,D39:H39,">"&0),"-") -> 21.428571 | K39: =IFERROR(MAX(D39:H39),"-") -> 52.857143 | L39: =IFERROR(_xlfn.XLOOKUP(P39,'Europcar rates'!G:G,'Europcar rates'!E:E),"-") -> 25.142857 | M39: =IFERROR((L39-I39)/I39,"-") -> -0.16824197 | N39: =IF(L39="-","⚪ Not Offered by Europcar",IF(L39<=I39*0.9,"✅ Below Market",IF(L39<=I39*1.1,"🟡 At Market","🔴 Above Market"))) -> ✅ Below Market | O39: =IF(L39="-","See opportunity analysis on dashboard",IF(L39<=I39*0.9,"Hold — Room to Increase Rate",IF(L39<=I39*1.1,"Hold — Well Positioned","Review Rate — Above Market"))) -> Hold — Room to Increase Rate | P39: Shannon Airport | Economy (Small Car)
A40: Shannon Airport | B40: Economy (Small Car) | C40: High Season Auto | D40: ='Competitor''s Rate'!N10 -> 45.428571 | E40: ='Competitor''s Rate'!O10 -> 45.285714 | F40: ='Competitor''s Rate'!P10 -> 110.85714 | G40: ='Competitor''s Rate'!Q10 -> 37.571429 | H40: ='Competitor''s Rate'!R10 -> 37.714286 | I40: =IFERROR(AVERAGEIF(D40:H40,">"&0),"-") -> 55.371429 | J40: =IFERROR(_xlfn.MINIFS(D40:H40,D40:H40,">"&0),"-") -> 37.571429 | K40: =IFERROR(MAX(D40:H40),"-") -> 110.85714 | L40: =IFERROR(_xlfn.XLOOKUP(P40,'Europcar rates'!G:G,'Europcar rates'!F:F),"-") -> 43.285714 | M40: =IFERROR((L40-I40)/I40,"-") -> -0.21826625 | N40: =IF(L40="-","⚪ Not Offered by Europcar",IF(L40<=I40*0.9,"✅ Below Market",IF(L40<=I40*1.1,"🟡 At Market","🔴 Above Market"))) -> ✅ Below Market | O40: =IF(L40="-","See opportunity analysis on dashboard",IF(L40<=I40*0.9,"Hold — Room to Increase Rate",IF(L40<=I40*1.1,"Hold — Well Positioned","Review Rate — Above Market"))) -> Hold — Room to Increase Rate | P40: Shannon Airport | Economy (Small Car)
...

Sheet Dashboard
A1: PRICING DASHBOARD — EUROPCAR IRELAND vs MARKET
A2: Data: rentalcars.com | Collected: 29 Apr 2026 | Rates in €/day | Formulas pull from Variance Analysis sheet
A4: SECTION 1 — HIGH SEASON AUTO: EUROPCAR vs COMPETITOR AVERAGE BY LOCATION
A5: Location | B5: Europcar Avg (€/day) | C5: Competitor Avg (€/day) | D5: Difference (€) | E5: Difference (%) | F5: Position
A6: Dublin Airport | B6: =IFERROR(AVERAGE('Variance Analysis'!L8,'Variance Analysis'!L12,'Variance Analysis'!L16,'Variance Analysis'!L20),"-") -> 60.035714 | C6: =IFERROR(AVERAGE('Variance Analysis'!I8,'Variance Analysis'!I12,'Variance Analysis'!I16,'Variance Analysis'!I20),"-") -> 105.00893 | D6: =IFERROR(B6-C6,"-") -> -44.973214 | E6: =IFERROR((B6-C6)/C6,"-") -> -0.42827991 | F6: =IFERROR(IF(B6<=C6*0.9,"✅ Below Market",IF(B6<=C6*1.1,"🟡 At Market","🔴 Above Market")),"-") -> ✅ Below Market
A7: Cork Airport | B7: =IFERROR(AVERAGE('Variance Analysis'!L24,'Variance Analysis'!L28,'Variance Analysis'!L32),"-") -> 48.428571 | C7: =IFERROR(AVERAGE('Variance Analysis'!I24,'Variance Analysis'!I28,'Variance Analysis'!I32),"-") -> 62.047619 | D7: =IFERROR(B7-C7,"-") -> -13.619048 | E7: =IFERROR((B7-C7)/C7,"-") -> -0.21949348 | F7: =IFERROR(IF(B7<=C7*0.9,"✅ Below Market",IF(B7<=C7*1.1,"🟡 At Market","🔴 Above Market")),"-") -> ✅ Below Market
A8: Shannon Airport | B8: =IFERROR(AVERAGE('Variance Analysis'!L40,'Variance Analysis'!L44,'Variance Analysis'!L48),"-") -> 48.428571 | C8: =IFERROR(AVERAGE('Variance Analysis'!I40,'Variance Analysis'!I44,'Variance Analysis'!I48),"-") -> 62.361905 | D8: =IFERROR(B8-C8,"-") -> -13.933333 | E8: =IFERROR((B8-C8)/C8,"-") -> -0.223427 | F8: =IFERROR(IF(B8<=C8*0.9,"✅ Below Market",IF(B8<=C8*1.1,"🟡 At Market","🔴 Above Market")),"-") -> ✅ Below Market
A9: Galway | B9: =IFERROR(AVERAGE('Variance Analysis'!L56,'Variance Analysis'!L60,'Variance Analysis'!L64),"-") -> 50.952381 | C9: =IFERROR(AVERAGE('Variance Analysis'!I56,'Variance Analysis'!I60,'Variance Analysis'!I64),"-") -> 88.261905 | D9: =IFERROR(B9-C9,"-") -> -37.309524 | E9: =IFERROR((B9-C9)/C9,"-") -> -0.42271378 | F9: =IFERROR(IF(B9<=C9*0.9,"✅ Below Market",IF(B9<=C9*1.1,"🟡 At Market","🔴 Above Market")),"-") -> ✅ Below Market
A12: SECTION 2 — POSITION HEATMAP: HIGH SEASON AUTO BY LOCATION & CLASS
A13: Location | B13: Economy | C13: Compact | D13: SUV | E13: People Carrier
A14: Dublin Airport | B14: ='Variance Analysis'!N8 -> ✅ Below Market | C14: ='Variance Analysis'!N12 -> ✅ Below Market | D14: ='Variance Analysis'!N16 -> ✅ Below Market | E14: ='Variance Analysis'!N20 -> ✅ Below Market
A15: Cork Airport | B15: ='Variance Analysis'!N24 -> ✅ Below Market | C15: ='Variance Analysis'!N28 -> ✅ Below Market | D15: ='Variance Analysis'!N32 -> ✅ Below Market | E15: ='Variance Analysis'!N36 -> ⚪ Not Offered by Europcar
A16: Shannon Airport | B16: ='Variance Analysis'!N40 -> ✅ Below Market | C16: ='Variance Analysis'!N44 -> ✅ Below Market | D16: ='Variance Analysis'!N48 -> ✅ Below Market | E16: ='Variance Analysis'!N52 -> ⚪ Not Offered by Europcar
A17: Galway | B17: ='Variance Analysis'!N56 -> ✅ Below Market | C17: ='Variance Analysis'!N60 -> ✅ Below Market | D17: ='Variance Analysis'!N64 -> ✅ Below Market | E17: ='Variance Analysis'!N68 -> ⚪ Not Offered by Europcar
A19: SECTION 1 — HIGH SEASON MANUAL : EUROPCAR vs COMPETITOR AVERAGE BY LOCATION
A20: Location | B20: Europcar Avg (€/day) | C20: Competitor Avg (€/day) | D20: Difference (€) | E20: Difference (%) | F20: Position
A21: Dublin Airport | B21: =IFERROR(AVERAGE('Variance Analysis'!L7,'Variance Analysis'!L11,'Variance Analysis'!L15),"-") -> 28.238095 | C21: =IFERROR(AVERAGE('Variance Analysis'!I7,'Variance Analysis'!I11,'Variance Analysis'!I15),"-") -> 35.885714 | D21: =IFERROR(B21-C21,"-") -> -7.647619 | E21: =IFERROR((B21-C21)/C21,"-") -> -0.2131104 | F21: =IFERROR(IF(B21<=C21*0.9,"✅ Below Market",IF(B21<=C21*1.1,"🟡 At Market","🔴 Above Market")),"-") -> ✅ Below Market
A22: Cork Airport | B22: =IFERROR(AVERAGE('Variance Analysis'!L23,'Variance Analysis'!L27,'Variance Analysis'!L31),"-") -> 28.238095 | C22: =IFERROR(AVERAGE('Variance Analysis'!I23,'Variance Analysis'!I27,'Variance Analysis'!I31),"-") -> 36.980952 | D22: =IFERROR(B22-C22,"-") -> -8.7428571 | E22: =IFERROR((B22-C22)/C22,"-") -> -0.23641514 | F22: =IFERROR(IF(B22<=C22*0.9,"✅ Below Market",IF(B22<=C22*1.1,"🟡 At Market","🔴 Above Market")),"-") -> ✅ Below Market
A23: Shannon Airport | B23: =IFERROR(AVERAGE('Variance Analysis'!L39,'Variance Analysis'!L43,'Variance Analysis'!L47),"-") -> 28.238095 | C23: =IFERROR(AVERAGE('Variance Analysis'!I39,'Variance Analysis'!I43,'Variance Analysis'!I47),"-") -> 32.990476 | D23: =IFERROR(B23-C23,"-") -> -4.752381 | E23: =IFERROR((B23-C23)/C23,"-") -> -0.14405312 | F23: =IFERROR(IF(B23<=C23*0.9,"✅ Below Market",IF(B23<=C23*1.1,"🟡 At Market","🔴 Above Market")),"-") -> ✅ Below Market
A24: Galway | B24: =IFERROR(AVERAGE('Variance Analysis'!L55,'Variance Analysis'!L59,'Variance Analysis'!L63),"-") -> 30.190476 | C24: =IFERROR(AVERAGE('Variance Analysis'!I55,'Variance Analysis'!I59,'Variance Analysis'!I63),"-") -> 61.166667 | D24: =IFERROR(B24-C24,"-") -> -30.97619 | E24: =IFERROR((B24-C24)/C24,"-") -> -0.50642273 | F24: =IFERROR(IF(B24<=C24*0.9,"✅ Below Market",IF(B24<=C24*1.1,"🟡 At Market","🔴 Above Market")),"-") -> ✅ Below Market
A26: SECTION 2 — POSITION HEATMAP: HIGH SEASON MANUAL BY LOCATION & CLASS
A27: Location | B27: Economy | C27: Compact | D27: SUV | E27: People Carrier
A28: Dublin Airport | B28: ='Variance Analysis'!N7 -> ✅ Below Market | C28: ='Variance Analysis'!N11 -> ✅ Below Market | D28: ='Variance Analysis'!N15 -> ✅ Below Market | E28: ='Variance Analysis'!N19 -> ⚪ Not Offered by Europcar
A29: Cork Airport | B29: ='Variance Analysis'!N23 -> ✅ Below Market | C29: ='Variance Analysis'!N27 -> ✅ Below Market | D29: ='Variance Analysis'!N31 -> ✅ Below Market | E29: ='Variance Analysis'!N35 -> ⚪ Not Offered by Europcar
A30: Shannon Airport | B30: ='Variance Analysis'!N39 -> ✅ Below Market | C30: ='Variance Analysis'!N43 -> ✅ Below Market | D30: ='Variance Analysis'!N47 -> 🟡 At Market | E30: ='Variance Analysis'!N51 -> ⚪ Not Offered by Europcar
A31: Galway | B31: ='Variance Analysis'!N55 -> ✅ Below Market | C31: ='Variance Analysis'!N59 -> ✅ Below Market | D31: ='Variance Analysis'!N63 -> ✅ Below Market | E31: ='Variance Analysis'!N67 -> ⚪ Not Offered by Europcar
A35: SECTION 3 — KEY ANALYST INSIGHTS
A36: 1. Limited Competition in Galway | C36: Only Enterprise and Budget operate in Galway. Reduced competition may support higher pricing in this market with less pressure to match a broad competitor set.
A37: 2. People Carrier — Inverted Seasonality | C37: People Carrier low season rates exceed high season. Driven by corporate demand in June, limited fleet and fewer competitors offering this class outside peak tourist season.
A38: 3. Enterprise Premium Pricing | C38: Enterprise consistently prices significantly above all competitors across all locations — particularly Economy and Compact. Likely reflects a premium brand positioning strategy.
A39: 4. Cork & Shannon — No People Carrier (Europcar) | C39: No People Carrier availability at Cork or Shannon. Europcar could assess whether introducing this class represents a revenue opportunity.
A40: 5. Methodology Note | C40: Both seasons searched 29 Apr 2026. High season ~11 weeks ahead. Low season (June) ~6 weeks ahead. Live analysis would require rate-shopping at equivalent lead times for a fair comparison.
